[2024-06-20T06:12:15.586+0000] {local_task_job_runner.py:120} INFO - ::group::Pre task execution logs
[2024-06-20T06:12:15.615+0000] {taskinstance.py:2076} INFO - Dependencies all met for dep_context=non-requeueable deps ti=<TaskInstance: ml_pipeline.prepare_data manual__2024-06-20T06:11:27.702691+00:00 [queued]>
[2024-06-20T06:12:15.629+0000] {taskinstance.py:2076} INFO - Dependencies all met for dep_context=requeueable deps ti=<TaskInstance: ml_pipeline.prepare_data manual__2024-06-20T06:11:27.702691+00:00 [queued]>
[2024-06-20T06:12:15.631+0000] {taskinstance.py:2306} INFO - Starting attempt 2 of 3
[2024-06-20T06:12:15.656+0000] {taskinstance.py:2330} INFO - Executing <Task(PythonOperator): prepare_data> on 2024-06-20 06:11:27.702691+00:00
[2024-06-20T06:12:15.665+0000] {warnings.py:112} WARNING - /home/***/.local/lib/python3.12/site-packages/***/task/task_runner/standard_task_runner.py:61: DeprecationWarning: This process (pid=370) is multi-threaded, use of fork() may lead to deadlocks in the child.
  pid = os.fork()

[2024-06-20T06:12:15.666+0000] {standard_task_runner.py:90} INFO - Running: ['***', 'tasks', 'run', 'ml_pipeline', 'prepare_data', 'manual__2024-06-20T06:11:27.702691+00:00', '--job-id', '7', '--raw', '--subdir', 'DAGS_FOLDER/ml_pipeline.py', '--cfg-path', '/tmp/tmp2bn0vbd_']
[2024-06-20T06:12:15.668+0000] {standard_task_runner.py:63} INFO - Started process 372 to run task
[2024-06-20T06:12:15.668+0000] {standard_task_runner.py:91} INFO - Job 7: Subtask prepare_data
[2024-06-20T06:12:15.739+0000] {task_command.py:426} INFO - Running <TaskInstance: ml_pipeline.prepare_data manual__2024-06-20T06:11:27.702691+00:00 [running]> on host 56cacc86e873
[2024-06-20T06:12:15.870+0000] {taskinstance.py:2648} INFO - Exporting env vars: AIRFLOW_CTX_DAG_OWNER='RCH4CKERS' AIRFLOW_CTX_DAG_ID='ml_pipeline' AIRFLOW_CTX_TASK_ID='prepare_data' AIRFLOW_CTX_EXECUTION_DATE='2024-06-20T06:11:27.702691+00:00' AIRFLOW_CTX_TRY_NUMBER='2' AIRFLOW_CTX_DAG_RUN_ID='manual__2024-06-20T06:11:27.702691+00:00'
[2024-06-20T06:12:15.872+0000] {taskinstance.py:430} INFO - ::endgroup::
[2024-06-20T06:12:15.878+0000] {taskinstance.py:441} INFO - ::group::Post task execution logs
[2024-06-20T06:12:15.879+0000] {taskinstance.py:2905} ERROR - Task failed with exception
Traceback (most recent call last):
  File "/home/airflow/.local/lib/python3.12/site-packages/airflow/models/taskinstance.py", line 465, in _execute_task
    result = _execute_callable(context=context, **execute_callable_kwargs)
             ^^^^^^^^^^^^^^^^^^^^^^^^^^^^^^^^^^^^^^^^^^^^^^^^^^^^^^^^^^^^^
  File "/home/airflow/.local/lib/python3.12/site-packages/airflow/models/taskinstance.py", line 432, in _execute_callable
    return execute_callable(context=context, **execute_callable_kwargs)
           ^^^^^^^^^^^^^^^^^^^^^^^^^^^^^^^^^^^^^^^^^^^^^^^^^^^^^^^^^^^^
  File "/home/airflow/.local/lib/python3.12/site-packages/airflow/models/baseoperator.py", line 401, in wrapper
    return func(self, *args, **kwargs)
           ^^^^^^^^^^^^^^^^^^^^^^^^^^^
  File "/home/airflow/.local/lib/python3.12/site-packages/airflow/operators/python.py", line 235, in execute
    return_value = self.execute_callable()
                   ^^^^^^^^^^^^^^^^^^^^^^^
  File "/home/airflow/.local/lib/python3.12/site-packages/airflow/operators/python.py", line 252, in execute_callable
    return self.python_callable(*self.op_args, **self.op_kwargs)
           ^^^^^^^^^^^^^^^^^^^^^^^^^^^^^^^^^^^^^^^^^^^^^^^^^^^^^
  File "/opt/airflow/dags/ml_pipeline.py", line 24, in prepare_data
    data = pd.read_csv('data/data.csv')
           ^^^^^^^^^^^^^^^^^^^^^^^^^^^^
  File "/home/airflow/.local/lib/python3.12/site-packages/pandas/io/parsers/readers.py", line 948, in read_csv
    return _read(filepath_or_buffer, kwds)
           ^^^^^^^^^^^^^^^^^^^^^^^^^^^^^^^
  File "/home/airflow/.local/lib/python3.12/site-packages/pandas/io/parsers/readers.py", line 611, in _read
    parser = TextFileReader(filepath_or_buffer, **kwds)
             ^^^^^^^^^^^^^^^^^^^^^^^^^^^^^^^^^^^^^^^^^^
  File "/home/airflow/.local/lib/python3.12/site-packages/pandas/io/parsers/readers.py", line 1448, in __init__
    self._engine = self._make_engine(f, self.engine)
                   ^^^^^^^^^^^^^^^^^^^^^^^^^^^^^^^^^
  File "/home/airflow/.local/lib/python3.12/site-packages/pandas/io/parsers/readers.py", line 1705, in _make_engine
    self.handles = get_handle(
                   ^^^^^^^^^^^
  File "/home/airflow/.local/lib/python3.12/site-packages/pandas/io/common.py", line 863, in get_handle
    handle = open(
             ^^^^^
FileNotFoundError: [Errno 2] No such file or directory: 'data/data.csv'
[2024-06-20T06:12:15.902+0000] {taskinstance.py:1206} INFO - Marking task as UP_FOR_RETRY. dag_id=ml_pipeline, task_id=prepare_data, run_id=manual__2024-06-20T06:11:27.702691+00:00, execution_date=20240620T061127, start_date=20240620T061215, end_date=20240620T061215
[2024-06-20T06:12:15.922+0000] {standard_task_runner.py:110} ERROR - Failed to execute job 7 for task prepare_data ([Errno 2] No such file or directory: 'data/data.csv'; 372)
[2024-06-20T06:12:15.965+0000] {local_task_job_runner.py:240} INFO - Task exited with return code 1
[2024-06-20T06:12:15.990+0000] {taskinstance.py:3503} INFO - 0 downstream tasks scheduled from follow-on schedule check
[2024-06-20T06:12:15.993+0000] {local_task_job_runner.py:222} INFO - ::endgroup::
