[2024-06-20T07:15:16.732+0000] {local_task_job_runner.py:120} INFO - ::group::Pre task execution logs
[2024-06-20T07:15:16.749+0000] {taskinstance.py:2076} INFO - Dependencies all met for dep_context=non-requeueable deps ti=<TaskInstance: ml_pipeline.prepare_data manual__2024-06-20T07:04:16.732605+00:00 [queued]>
[2024-06-20T07:15:16.755+0000] {taskinstance.py:2076} INFO - Dependencies all met for dep_context=requeueable deps ti=<TaskInstance: ml_pipeline.prepare_data manual__2024-06-20T07:04:16.732605+00:00 [queued]>
[2024-06-20T07:15:16.756+0000] {taskinstance.py:2306} INFO - Starting attempt 2 of 2
[2024-06-20T07:15:16.770+0000] {taskinstance.py:2330} INFO - Executing <Task(PythonOperator): prepare_data> on 2024-06-20 07:04:16.732605+00:00
[2024-06-20T07:15:16.777+0000] {standard_task_runner.py:90} INFO - Running: ['***', 'tasks', 'run', 'ml_pipeline', 'prepare_data', 'manual__2024-06-20T07:04:16.732605+00:00', '--job-id', '24', '--raw', '--subdir', 'DAGS_FOLDER/ml_pipeline.py', '--cfg-path', '/tmp/tmp5w7_fbbg']
[2024-06-20T07:15:16.779+0000] {standard_task_runner.py:91} INFO - Job 24: Subtask prepare_data
[2024-06-20T07:15:16.779+0000] {warnings.py:112} WARNING - /home/***/.local/lib/python3.12/site-packages/***/task/task_runner/standard_task_runner.py:61: DeprecationWarning: This process (pid=52) is multi-threaded, use of fork() may lead to deadlocks in the child.
  pid = os.fork()

[2024-06-20T07:15:16.780+0000] {standard_task_runner.py:63} INFO - Started process 54 to run task
[2024-06-20T07:15:16.827+0000] {task_command.py:426} INFO - Running <TaskInstance: ml_pipeline.prepare_data manual__2024-06-20T07:04:16.732605+00:00 [running]> on host 9e16cb9136e3
[2024-06-20T07:15:16.921+0000] {taskinstance.py:2648} INFO - Exporting env vars: AIRFLOW_CTX_DAG_OWNER='RCH4CKERS' AIRFLOW_CTX_DAG_ID='ml_pipeline' AIRFLOW_CTX_TASK_ID='prepare_data' AIRFLOW_CTX_EXECUTION_DATE='2024-06-20T07:04:16.732605+00:00' AIRFLOW_CTX_TRY_NUMBER='2' AIRFLOW_CTX_DAG_RUN_ID='manual__2024-06-20T07:04:16.732605+00:00'
[2024-06-20T07:15:16.923+0000] {taskinstance.py:430} INFO - ::endgroup::
[2024-06-20T07:15:16.945+0000] {taskinstance.py:441} INFO - ::group::Post task execution logs
[2024-06-20T07:15:16.946+0000] {taskinstance.py:2905} ERROR - Task failed with exception
Traceback (most recent call last):
  File "/home/airflow/.local/lib/python3.12/site-packages/airflow/models/taskinstance.py", line 465, in _execute_task
    result = _execute_callable(context=context, **execute_callable_kwargs)
             ^^^^^^^^^^^^^^^^^^^^^^^^^^^^^^^^^^^^^^^^^^^^^^^^^^^^^^^^^^^^^
  File "/home/airflow/.local/lib/python3.12/site-packages/airflow/models/taskinstance.py", line 432, in _execute_callable
    return execute_callable(context=context, **execute_callable_kwargs)
           ^^^^^^^^^^^^^^^^^^^^^^^^^^^^^^^^^^^^^^^^^^^^^^^^^^^^^^^^^^^^
  File "/home/airflow/.local/lib/python3.12/site-packages/airflow/models/baseoperator.py", line 401, in wrapper
    return func(self, *args, **kwargs)
           ^^^^^^^^^^^^^^^^^^^^^^^^^^^
  File "/home/airflow/.local/lib/python3.12/site-packages/airflow/operators/python.py", line 235, in execute
    return_value = self.execute_callable()
                   ^^^^^^^^^^^^^^^^^^^^^^^
  File "/home/airflow/.local/lib/python3.12/site-packages/airflow/operators/python.py", line 252, in execute_callable
    return self.python_callable(*self.op_args, **self.op_kwargs)
           ^^^^^^^^^^^^^^^^^^^^^^^^^^^^^^^^^^^^^^^^^^^^^^^^^^^^^
  File "/opt/airflow/dags/ml_pipeline.py", line 146, in prepare_data
    train.to_csv('../data/train.csv', index=False)
  File "/home/airflow/.local/lib/python3.12/site-packages/pandas/core/generic.py", line 3902, in to_csv
    return DataFrameRenderer(formatter).to_csv(
           ^^^^^^^^^^^^^^^^^^^^^^^^^^^^^^^^^^^^
  File "/home/airflow/.local/lib/python3.12/site-packages/pandas/io/formats/format.py", line 1152, in to_csv
    csv_formatter.save()
  File "/home/airflow/.local/lib/python3.12/site-packages/pandas/io/formats/csvs.py", line 247, in save
    with get_handle(
         ^^^^^^^^^^^
  File "/home/airflow/.local/lib/python3.12/site-packages/pandas/io/common.py", line 739, in get_handle
    check_parent_directory(str(handle))
  File "/home/airflow/.local/lib/python3.12/site-packages/pandas/io/common.py", line 604, in check_parent_directory
    raise OSError(rf"Cannot save file into a non-existent directory: '{parent}'")
OSError: Cannot save file into a non-existent directory: '../data'
[2024-06-20T07:15:16.967+0000] {taskinstance.py:1206} INFO - Marking task as FAILED. dag_id=ml_pipeline, task_id=prepare_data, run_id=manual__2024-06-20T07:04:16.732605+00:00, execution_date=20240620T070416, start_date=20240620T071516, end_date=20240620T071516
[2024-06-20T07:15:16.979+0000] {standard_task_runner.py:110} ERROR - Failed to execute job 24 for task prepare_data (Cannot save file into a non-existent directory: '../data'; 54)
[2024-06-20T07:15:16.995+0000] {local_task_job_runner.py:240} INFO - Task exited with return code 1
[2024-06-20T07:15:17.004+0000] {local_task_job_runner.py:222} INFO - ::endgroup::
